<mujoco>

  <compiler inertiafromgeom="true"/>
  <default>
    <!-- <geom contype="0" friction="1 0.1 0.1" rgba="0.4 0.33 0.26 1.0"/> -->
    <tendon/>
    <motor ctrlrange="-2 2"/>
  </default>
  <option gravity="0 0 -9.81" timestep="0.02" />

 <asset>
    <texture type="skybox" builtin="gradient" rgb1="0.8 0.8 0.8" rgb2="0 0 0" width="512" height="3072"/>
    <texture name="floor_tex" type="2d" builtin="checker" rgb1=".2 .3 .4" rgb2=".1 .2 .3" width="100" height="100" />
    <material name="floor_material" texture="floor_tex" texuniform="true" />
  </asset>

  <worldbody>
    <light cutoff="100" diffuse="1 1 1" dir="-0 0 -1.2" directional="true" exponent="1" pos="0 0 1.3" specular=".1 .1 .1"/>
    <geom conaffinity="1" condim="3" material="floor_material" name="floor" pos="0 0 -0.5" size="40 40 40" type="plane" rgba="0.5 0.5 0.5 1.0"/>        <!-- 0 -->
    <!-- <light diffuse=".5 .5 .5" pos="0 0 3" dir="0 0 -1"/> -->z

    <body name="base">
        <joint type="free" name="free"/>
  
        <geom name="lower" type="box" size="0.1 0.1 1" quat="0.707107 0 0.707107 0" pos="0 0 0" mass="4"/>                                          <!-- 2 -->
        <geom name="upper" type="box" size="0.1 0.1 4" quat="0  0.707107 0 0" pos="0 0 4.1" mass="8"/>                                                  <!-- 1 -->


        <body name="top">
          <geom name="top" type="sphere" size="0.1 0.1" mass="1e-5" pos="0 0 8"/>                                                                                        <!-- 3 -->
        </body>

        <body name="right_wheel" pos="1.15 0 0.05">
          <geom name="right_wheel" type="cylinder" size="0.4125 0.125" quat="0 0.707107 0 0.707107" mass="26.5"/>                                <!-- 4 -->
          <joint name="right_wheel" type="hinge" axis="-1 0 0"/>
        </body>

        <body name="left_wheel" pos="-1.15 0 0.05">
          <geom name="left_wheel" type="cylinder" size="0.4125 0.125" quat="0 0.707107 0 0.707107" mass="26.5"/>                                   <!-- 5 -->
          <joint name="left_wheel" type="hinge" axis="-1 0 0"/>
        </body>

    </body>
  </worldbody>

  <equality>
          <joint joint1="left_wheel" joint2="right_wheel" polycoef="0 1 0 0 0"/>"
  </equality>

  <actuator>
    <motor gear="200" joint="left_wheel" name="left_wheel" ctrlrange="-1 1"/>
  </actuator>j



</mujoco>